Failure # 1 (occurred at 2021-08-26_10-56-05)
Traceback (most recent call last):
  File "/home/uceezs0/.conda/envs/dgl_5/lib/python3.6/site-packages/ray/tune/trial_runner.py", line 471, in _process_trial
    result = self.trial_executor.fetch_result(trial)
  File "/home/uceezs0/.conda/envs/dgl_5/lib/python3.6/site-packages/ray/tune/ray_trial_executor.py", line 430, in fetch_result
    result = ray.get(trial_future[0], DEFAULT_GET_TIMEOUT)
  File "/home/uceezs0/.conda/envs/dgl_5/lib/python3.6/site-packages/ray/worker.py", line 1538, in get
    raise value.as_instanceof_cause()
  File "<string>", line None
ray.exceptions.RayTaskError(SyntaxError): <no detail available>

